{
 "cells": [
  {
   "cell_type": "markdown",
   "id": "9a7833da",
   "metadata": {},
   "source": [
    "# 12th Feb Assignment 2023"
   ]
  },
  {
   "cell_type": "markdown",
   "id": "63281e2f",
   "metadata": {},
   "source": [
    "# Exception handling-1\n"
   ]
  },
  {
   "cell_type": "markdown",
   "id": "ea408b5c",
   "metadata": {},
   "source": [
    "### Q1. What is an Exception in python? Write the difference between Exceptions and Syntax errors."
   ]
  },
  {
   "cell_type": "markdown",
   "id": "5b40a3a4",
   "metadata": {},
   "source": [
    "When an exception occurs, Python pauses the usual flow of the programme and raises an exception object with details about the issue. The software can then manage the exception by showing an error message, recording the error, or attempting to recover from the problem."
   ]
  },
  {
   "cell_type": "markdown",
   "id": "9089770e",
   "metadata": {},
   "source": [
    "* Syntax errors, on the other hand, arise when the Python interpreter encounters code that breaks the Python language's rules. Syntax problems are often identified by the interpreter during the parsing process, prior to execution of the code. Misspelled keywords, missing colons or parentheses, and incorrect operators are all examples of syntax problems."
   ]
  },
  {
   "cell_type": "markdown",
   "id": "0102a28c",
   "metadata": {},
   "source": [
    "* The primary distinction between exceptions and syntax mistakes is that exceptions occur during programme execution, whereas syntax errors are identified before the programme is performed. Exceptions are frequently generated by causes outside the programmer's control, such as improper input or network failures, whereas syntax errors are usually caused by faults in the code that the programmer can address."
   ]
  },
  {
   "cell_type": "markdown",
   "id": "fab5637c",
   "metadata": {},
   "source": [
    "### Q2. what happend when an exception is not handle? Explain with an example?"
   ]
  },
  {
   "cell_type": "markdown",
   "id": "5dcd7fd8",
   "metadata": {},
   "source": [
    "When an exception is not handled in a Python programme, the application will quit abruptly and display an error message that the end user may find difficult to interpret. This can be an issue, especially if the application is meant for non-technical users, since it might cause annoyance and misunderstanding."
   ]
  },
  {
   "cell_type": "code",
   "execution_count": 2,
   "id": "36358774",
   "metadata": {},
   "outputs": [
    {
     "ename": "ZeroDivisionError",
     "evalue": "division by zero",
     "output_type": "error",
     "traceback": [
      "\u001b[1;31m---------------------------------------------------------------------------\u001b[0m",
      "\u001b[1;31mZeroDivisionError\u001b[0m                         Traceback (most recent call last)",
      "Input \u001b[1;32mIn [2]\u001b[0m, in \u001b[0;36m<cell line: 6>\u001b[1;34m()\u001b[0m\n\u001b[0;32m      3\u001b[0m     \u001b[38;5;28;01mreturn\u001b[39;00m result\n\u001b[0;32m      5\u001b[0m \u001b[38;5;66;03m# This will raise an exception because we are dividing by zero\u001b[39;00m\n\u001b[1;32m----> 6\u001b[0m \u001b[43mdivide\u001b[49m\u001b[43m(\u001b[49m\u001b[38;5;241;43m5\u001b[39;49m\u001b[43m,\u001b[49m\u001b[43m \u001b[49m\u001b[38;5;241;43m0\u001b[39;49m\u001b[43m)\u001b[49m\n",
      "Input \u001b[1;32mIn [2]\u001b[0m, in \u001b[0;36mdivide\u001b[1;34m(x, y)\u001b[0m\n\u001b[0;32m      1\u001b[0m \u001b[38;5;28;01mdef\u001b[39;00m \u001b[38;5;21mdivide\u001b[39m(x, y):\n\u001b[1;32m----> 2\u001b[0m     result \u001b[38;5;241m=\u001b[39m \u001b[43mx\u001b[49m\u001b[43m \u001b[49m\u001b[38;5;241;43m/\u001b[39;49m\u001b[43m \u001b[49m\u001b[43my\u001b[49m\n\u001b[0;32m      3\u001b[0m     \u001b[38;5;28;01mreturn\u001b[39;00m result\n",
      "\u001b[1;31mZeroDivisionError\u001b[0m: division by zero"
     ]
    }
   ],
   "source": [
    "def divide(x, y):\n",
    "    result = x / y\n",
    "    return result\n",
    "\n",
    "# This will raise an exception because we are dividing by zero\n",
    "divide(5, 0)\n"
   ]
  },
  {
   "cell_type": "markdown",
   "id": "60a9c976",
   "metadata": {},
   "source": [
    "* If we call the divide function with divide(5, 0) as shown in the example, the program will terminate with a ZeroDivisionError message, because we are trying to divide by zero. The user will see this error message and may not know what to do to fix the problem, which can be frustrating."
   ]
  },
  {
   "cell_type": "code",
   "execution_count": null,
   "id": "d3a15049",
   "metadata": {},
   "outputs": [],
   "source": [
    "#To prevent the program from terminating abruptly and displaying the error message, we can handle the exception using a try-except block as follows:"
   ]
  },
  {
   "cell_type": "code",
   "execution_count": 3,
   "id": "d5c8ff01",
   "metadata": {},
   "outputs": [
    {
     "name": "stdout",
     "output_type": "stream",
     "text": [
      "Error: division by zero!\n"
     ]
    }
   ],
   "source": [
    "def divide(x, y):\n",
    "    try:\n",
    "        result = x / y\n",
    "    except ZeroDivisionError:\n",
    "        print(\"Error: division by zero!\")\n",
    "        result = None\n",
    "    return result\n",
    "\n",
    "# This will return None instead of raising an exception\n",
    "divide(5, 0)\n"
   ]
  },
  {
   "cell_type": "code",
   "execution_count": null,
   "id": "4fd5632c",
   "metadata": {},
   "outputs": [],
   "source": []
  },
  {
   "cell_type": "markdown",
   "id": "ddcbb67b",
   "metadata": {},
   "source": [
    "### Q3. which python statements are used to catch and handle exception? Explain with an example?\n"
   ]
  },
  {
   "cell_type": "markdown",
   "id": "c6317645",
   "metadata": {},
   "source": [
    "To capture and manage exceptions in Python, we utilise the try and except commands. The try statement is used to surround code that may throw an exception, and the except statement is used to handle any exceptions that are thrown. Here's an example of using try and except statements:"
   ]
  },
  {
   "cell_type": "code",
   "execution_count": 4,
   "id": "3cda74a4",
   "metadata": {},
   "outputs": [
    {
     "name": "stdout",
     "output_type": "stream",
     "text": [
      "Enter a number: 67\n",
      "Enter another number: 34\n",
      "Result is: 1.9705882352941178\n"
     ]
    }
   ],
   "source": [
    "try:\n",
    "    # code that might raise an exception\n",
    "    num1 = int(input(\"Enter a number: \"))\n",
    "    num2 = int(input(\"Enter another number: \"))\n",
    "    result = num1 / num2\n",
    "    print(\"Result is:\", result)\n",
    "except ZeroDivisionError:\n",
    "    # handle the ZeroDivisionError exception\n",
    "    print(\"Error: division by zero!\")\n",
    "except ValueError:\n",
    "    # handle the ValueError exception\n",
    "    print(\"Error: invalid input!\")\n"
   ]
  },
  {
   "cell_type": "markdown",
   "id": "a2ab9745",
   "metadata": {},
   "source": [
    "### Q4.Explain with an example:\n",
    "* try and else\n",
    "* finally\n",
    "* raised"
   ]
  },
  {
   "cell_type": "markdown",
   "id": "f99de412",
   "metadata": {},
   "source": [
    "* try and else:-\n",
    "\n",
    "   * In Python, we may combine the try and else expressions to manage exceptions and execute code that should always run whether or not an exception is thrown. The try statement is used to surround code that may throw an exception, and the else statement is used to execute code that should be executed if no exception is thrown. Here's an illustration:"
   ]
  },
  {
   "cell_type": "code",
   "execution_count": 5,
   "id": "5d40e930",
   "metadata": {},
   "outputs": [
    {
     "name": "stdout",
     "output_type": "stream",
     "text": [
      "Enter a number: 55\n",
      "Enter another number: 78\n",
      "Result is: 0.7051282051282052\n"
     ]
    }
   ],
   "source": [
    "try:\n",
    "    num1 = int(input(\"Enter a number: \"))\n",
    "    num2 = int(input(\"Enter another number: \"))\n",
    "    result = num1 / num2\n",
    "except ZeroDivisionError:\n",
    "    print(\"Error: division by zero!\")\n",
    "else:\n",
    "    print(\"Result is:\", result)\n"
   ]
  },
  {
   "cell_type": "markdown",
   "id": "e75fff34",
   "metadata": {},
   "source": [
    "* Finally:-\n",
    "    * In Python, we may use the finally statement to execute code that should always be executed, regardless of whether an exception is triggered. The finally statement is used to surround code that should always run and will be executed whether or not an exception is triggered. Here's an illustration:"
   ]
  },
  {
   "cell_type": "code",
   "execution_count": 6,
   "id": "742608ff",
   "metadata": {},
   "outputs": [
    {
     "name": "stdout",
     "output_type": "stream",
     "text": [
      "Error: file not found!\n"
     ]
    },
    {
     "ename": "NameError",
     "evalue": "name 'file' is not defined",
     "output_type": "error",
     "traceback": [
      "\u001b[1;31m---------------------------------------------------------------------------\u001b[0m",
      "\u001b[1;31mNameError\u001b[0m                                 Traceback (most recent call last)",
      "Input \u001b[1;32mIn [6]\u001b[0m, in \u001b[0;36m<cell line: 1>\u001b[1;34m()\u001b[0m\n\u001b[0;32m      7\u001b[0m     \u001b[38;5;28mprint\u001b[39m(\u001b[38;5;124m\"\u001b[39m\u001b[38;5;124mFile contents:\u001b[39m\u001b[38;5;124m\"\u001b[39m, file\u001b[38;5;241m.\u001b[39mread())\n\u001b[0;32m      8\u001b[0m \u001b[38;5;28;01mfinally\u001b[39;00m:\n\u001b[1;32m----> 9\u001b[0m     \u001b[43mfile\u001b[49m\u001b[38;5;241m.\u001b[39mclose()\n\u001b[0;32m     10\u001b[0m     \u001b[38;5;28mprint\u001b[39m(\u001b[38;5;124m\"\u001b[39m\u001b[38;5;124mFile closed.\u001b[39m\u001b[38;5;124m\"\u001b[39m)\n",
      "\u001b[1;31mNameError\u001b[0m: name 'file' is not defined"
     ]
    }
   ],
   "source": [
    "try:\n",
    "    file = open(\"myfile.txt\", \"r\")\n",
    "    # code that reads from the file\n",
    "except FileNotFoundError:\n",
    "    print(\"Error: file not found!\")\n",
    "else:\n",
    "    print(\"File contents:\", file.read())\n",
    "finally:\n",
    "    file.close()\n",
    "    print(\"File closed.\")\n"
   ]
  },
  {
   "cell_type": "code",
   "execution_count": null,
   "id": "135270fa",
   "metadata": {},
   "outputs": [],
   "source": [
    "#In this example, we use try to open a file for reading and read its contents. If a FileNotFoundError is raised, the program will handle it by printing \"Error: file not found!\""
   ]
  },
  {
   "cell_type": "markdown",
   "id": "a258b44a",
   "metadata": {},
   "source": [
    "* raised:-\n",
    "    * To manually raise an exception in Python, use the raise statement. We can throw built-in exceptions like ValueError, TypeError, or IndexError, or construct our own custom exceptions. Here's an example of raising an exception:"
   ]
  },
  {
   "cell_type": "code",
   "execution_count": 7,
   "id": "7d7e6622",
   "metadata": {},
   "outputs": [
    {
     "ename": "ValueError",
     "evalue": "Age cannot be negative!",
     "output_type": "error",
     "traceback": [
      "\u001b[1;31m---------------------------------------------------------------------------\u001b[0m",
      "\u001b[1;31mValueError\u001b[0m                                Traceback (most recent call last)",
      "Input \u001b[1;32mIn [7]\u001b[0m, in \u001b[0;36m<cell line: 9>\u001b[1;34m()\u001b[0m\n\u001b[0;32m      6\u001b[0m     \u001b[38;5;28;01melse\u001b[39;00m:\n\u001b[0;32m      7\u001b[0m         \u001b[38;5;28mprint\u001b[39m(\u001b[38;5;124m\"\u001b[39m\u001b[38;5;124mAge is valid.\u001b[39m\u001b[38;5;124m\"\u001b[39m)\n\u001b[1;32m----> 9\u001b[0m \u001b[43mvalidate_age\u001b[49m\u001b[43m(\u001b[49m\u001b[38;5;241;43m-\u001b[39;49m\u001b[38;5;241;43m5\u001b[39;49m\u001b[43m)\u001b[49m   \u001b[38;5;66;03m# raises ValueError with \"Age cannot be negative!\" message\u001b[39;00m\n\u001b[0;32m     10\u001b[0m validate_age(\u001b[38;5;241m150\u001b[39m)  \u001b[38;5;66;03m# raises ValueError with \"Age cannot be greater than 120!\" message\u001b[39;00m\n\u001b[0;32m     11\u001b[0m validate_age(\u001b[38;5;241m25\u001b[39m)\n",
      "Input \u001b[1;32mIn [7]\u001b[0m, in \u001b[0;36mvalidate_age\u001b[1;34m(age)\u001b[0m\n\u001b[0;32m      1\u001b[0m \u001b[38;5;28;01mdef\u001b[39;00m \u001b[38;5;21mvalidate_age\u001b[39m(age):\n\u001b[0;32m      2\u001b[0m     \u001b[38;5;28;01mif\u001b[39;00m age \u001b[38;5;241m<\u001b[39m \u001b[38;5;241m0\u001b[39m:\n\u001b[1;32m----> 3\u001b[0m         \u001b[38;5;28;01mraise\u001b[39;00m \u001b[38;5;167;01mValueError\u001b[39;00m(\u001b[38;5;124m\"\u001b[39m\u001b[38;5;124mAge cannot be negative!\u001b[39m\u001b[38;5;124m\"\u001b[39m)\n\u001b[0;32m      4\u001b[0m     \u001b[38;5;28;01melif\u001b[39;00m age \u001b[38;5;241m>\u001b[39m \u001b[38;5;241m120\u001b[39m:\n\u001b[0;32m      5\u001b[0m         \u001b[38;5;28;01mraise\u001b[39;00m \u001b[38;5;167;01mValueError\u001b[39;00m(\u001b[38;5;124m\"\u001b[39m\u001b[38;5;124mAge cannot be greater than 120!\u001b[39m\u001b[38;5;124m\"\u001b[39m)\n",
      "\u001b[1;31mValueError\u001b[0m: Age cannot be negative!"
     ]
    }
   ],
   "source": [
    "def validate_age(age):\n",
    "    if age < 0:\n",
    "        raise ValueError(\"Age cannot be negative!\")\n",
    "    elif age > 120:\n",
    "        raise ValueError(\"Age cannot be greater than 120!\")\n",
    "    else:\n",
    "        print(\"Age is valid.\")\n",
    "\n",
    "validate_age(-5)   # raises ValueError with \"Age cannot be negative!\" message\n",
    "validate_age(150)  # raises ValueError with \"Age cannot be greater than 120!\" message\n",
    "validate_age(25)   # prints \"Age is valid.\"\n"
   ]
  },
  {
   "cell_type": "markdown",
   "id": "f9bb113d",
   "metadata": {},
   "source": [
    "In this example, we construct the validate age function, which accepts an age as an input and validates it. We generate a ValueError with a suitable error message if the age is negative or larger than 120. Otherwise, \"Age is valid.\" is printed. When we call the function with an incorrect age, a ValueError with the accompanying error message is generated. When we call the function with a valid age, it prints \"Age is valid.\" and throws no exceptions."
   ]
  },
  {
   "cell_type": "markdown",
   "id": "0d92e6c6",
   "metadata": {},
   "source": [
    "### Q5. what are custom exception in python? why do we need custom exception? explain with an example"
   ]
  },
  {
   "cell_type": "markdown",
   "id": "5f2921ca",
   "metadata": {},
   "source": [
    "With Python, we may create our own custom exceptions to address certain issues in our programmes. Bespoke exceptions are subclasses of the built-in Exception class that allow us to give more informative error messages and more effectively handle certain problem conditions."
   ]
  },
  {
   "cell_type": "markdown",
   "id": "4681a6cd",
   "metadata": {},
   "source": [
    "* Custom exceptions are required because the built-in exceptions do not always adequately convey the nature of the mistake. For example, if we are developing a system that handles financial transactions, we may design a custom exception to manage scenarios in which the transaction amount exceeds the user's account balance. This may help us design more legible and maintainable code, as well as more effectively detect and manage specific faults."
   ]
  },
  {
   "cell_type": "code",
   "execution_count": 8,
   "id": "9bfaef44",
   "metadata": {},
   "outputs": [
    {
     "name": "stdout",
     "output_type": "stream",
     "text": [
      "Insufficient balance\n"
     ]
    }
   ],
   "source": [
    "class InsufficientBalanceError(Exception):\n",
    "    def __init__(self, message=\"Insufficient balance\"):\n",
    "        self.message = message\n",
    "        super().__init__(self.message)\n",
    "\n",
    "class BankAccount:\n",
    "    def __init__(self, balance):\n",
    "        self.balance = balance\n",
    "\n",
    "    def withdraw(self, amount):\n",
    "        if amount > self.balance:\n",
    "            raise InsufficientBalanceError()\n",
    "        else:\n",
    "            self.balance -= amount\n",
    "            print(\"Withdrawn:\", amount)\n",
    "            print(\"Remaining balance:\", self.balance)\n",
    "\n",
    "account = BankAccount(500)\n",
    "try:\n",
    "    account.withdraw(750)\n",
    "except InsufficientBalanceError as e:\n",
    "    print(e)\n"
   ]
  },
  {
   "cell_type": "markdown",
   "id": "51bba2cf",
   "metadata": {},
   "source": [
    "* We construct a custom exception named InsufficientBalanceError in this example, which inherits from the Exception class. We also construct a BankAccount class with a withdraw function that checks to see whether the desired withdrawal amount exceeds the account balance. If so, we throw an InsufficientBalanceError. If it isn't, we deduct the amount from the balance and publish the new balance."
   ]
  },
  {
   "cell_type": "markdown",
   "id": "2958ac44",
   "metadata": {},
   "source": [
    "* When we create a BankAccount instance with a balance of 500 and attempt to withdraw 750, the withdraw function throws an InsufficientBalanceError with the default message \"Insufficient balance\". Using a try/except block, we catch the exception and output the error message. We would have had to catch a more generic exception like ValueError or Exception and investigate the error message to discover the nature of the mistake if we hadn't specified a custom exception. We may make our code more legible and handle certain failures more effectively by building a custom exception."
   ]
  },
  {
   "cell_type": "markdown",
   "id": "f8d8cf22",
   "metadata": {},
   "source": [
    "### Q6. create a custom exception class. use this class to handle an exception?"
   ]
  },
  {
   "cell_type": "code",
   "execution_count": 9,
   "id": "66ec7f15",
   "metadata": {},
   "outputs": [
    {
     "name": "stdout",
     "output_type": "stream",
     "text": [
      "Caught custom exception: An error occurred in some_function\n"
     ]
    }
   ],
   "source": [
    "class CustomException(Exception):\n",
    "    pass\n",
    "\n",
    "def some_function():\n",
    "    raise CustomException(\"An error occurred in some_function\")\n",
    "\n",
    "try:\n",
    "    some_function()\n",
    "except CustomException as e:\n",
    "    print(\"Caught custom exception:\", e)\n"
   ]
  },
  {
   "cell_type": "markdown",
   "id": "92e286c4",
   "metadata": {},
   "source": [
    "* In this example, we define CustomException, a custom exception class that inherits from the built-in Exception class. There is no more functionality in this exception class, but we may add methods or properties to alter its behaviour as required.\n",
    "\n",
    "We also construct a some function that raises a CustomException object with a message. This replicates a mistake in a section of our code."
   ]
  },
  {
   "cell_type": "markdown",
   "id": "e882ef3e",
   "metadata": {},
   "source": [
    "* Then, we use a try/except block to catch the CustomException and output a message indicating that the exception was caught. If we didn't catch the CustomException, it would propagate up the call stack until it was caught by another try/except block or the programme crashed with an unhandled exception.\n",
    "\n",
    "Ultimately, custom exceptions can help us make our code more modular and manageable by making it easier to design and handle particular error circumstances."
   ]
  },
  {
   "cell_type": "markdown",
   "id": "30ad75b1",
   "metadata": {},
   "source": [
    "## Thank You"
   ]
  },
  {
   "cell_type": "code",
   "execution_count": null,
   "id": "1ac9a378",
   "metadata": {},
   "outputs": [],
   "source": []
  }
 ],
 "metadata": {
  "kernelspec": {
   "display_name": "Python 3 (ipykernel)",
   "language": "python",
   "name": "python3"
  },
  "language_info": {
   "codemirror_mode": {
    "name": "ipython",
    "version": 3
   },
   "file_extension": ".py",
   "mimetype": "text/x-python",
   "name": "python",
   "nbconvert_exporter": "python",
   "pygments_lexer": "ipython3",
   "version": "3.9.12"
  }
 },
 "nbformat": 4,
 "nbformat_minor": 5
}
